Workbook

Sheet Info
A3: May Material Bottlenecks hamper the Global Energy Transition towards 1.5°C target?
A6: Simon Schlichenmaiera Tobias Naeglera,*
A8: a Department of Energy Systems Analysis, Institute of Networked Energy Systems, German Aerospace Center (DLR), Stuttgart, Germany
A10: * Corresponding author. Contact: phone: +49 (0)711 6862-775, email: Tobias.Naegler@dlr.de
A13: Acknowledgements
A15: This Reserach was partly founded by the German Federal Ministry of Education and Research (BMBF)
A16: under the project number 03SFK5B0 as part of the project ARIADNE.
A18: The authors thank Tobias Junne (formerly at DLR) for valuable, inspiring discussions.
A19: Thanks also to Thomas Pregger and Sonja Simon (both DLR) for providing the data for the LDF scenario.

Sheet Content & References
C2: Sheet | E2: Reference: | H2: Colourcode:
B3: Data | C3: Framework Data | E3: [1] | F3: USGS - Mineral Commodity Summaries 1996-2020 | H3: calculated here
C4: Data Demand Energy Sector | E4: [2] | F4: USGS - Mineral Yearbook PGM 1994-2017 | H4: value set manually, can be changed
C5: Data Non-Energy Sector | E5: [3] | F5: Johnson Matthey - Market Data Table Iridium 2005-2013 | H5: inter- or extrapolated
B6: Mineral | C6: Cadmium | E6: [4] | F6: Johnson Matthey - PGM Market Report Nov. 2014-Feb.2020 | H6: value is imported from another cell / sheet
C7: Cerium | E7: [5] | F7: https://data.worldbank.org/indicator/NY.GDP.MKTP.PP.KD | H7: statistical data
C8: Cobalt | E8: [6] | F8: https://data.worldbank.org/indicator/NY.GDP.MKTP.KD.ZG | H8: value must not be changed
C9: Dysprosium | E9: [7] | F9: Teske 2019. Achieving the Paris Climate Agreement Goals
C10: Gadolinium | E10: [8] | F10: UNEP 2011. Recycling Rates of Metals: A Status Report
C11: Gallium | E11: [9] | F11: European Commission 2020. Study on the EU's list of Critical Raw Materials (2020) - Critical / Non-Critical Materials Factsheets
C12: Germanium | E12: [10] | F12: Junne et al. 2020. Critical materials in global low-carbon energy scenarios: The case for neodymium, dysprosium, lithium, and cobalt
C13: Indium | E13: [11] | F13: European Commission 2017. COMMUNICATION FROM THE COMMISSION TO THE EUROPEAN PARLIAMENT, THE COUNCIL, THE EUROPEAN ECONOMIC AND SOCIAL COMMITTEE AND THE COMMITTEE OF THE REGIONS - on the 2017 list of Critical Raw Materials for the EU
C14: Iridium | E14: [12] | F14: Zhou et al. 2017. Global Potential of Rare Earth Resources and Rare Earth Demand from Clean Technologies
C15: Lanthanum | E15: [13] | F15: European Commission 2017. Study on the EU's list of Critical Raw Materials (2020) - Critical / Non-Critical Materials Factsheets
C16: Lithium | E16: [14] | F16: The Application of Zirconium Products (samaterials.com)
C17: Manganese | E17: [15] | F17: Harper et al. 2011. Tracking the Metal of the Goblins: Cobalt's Cycle of Use
C18: Neodymium | E18: [16] | F18: Binnemans et al. 2013. Recycling of rare eraths; a critical review
C19: Nickel | E19: [17] | F19: Angerer et al. 2009. Lithium für Zukunftstechnologien - Nachfrage und Angebot unter besonderer Berücksichtigung der Elektromobilität
C20: Platinum | E20: [18] | F20: Schulze & Buchert 2016. Estimates of global REE recycling potentials from NdFeB magnet material
... C23: Selenium | E23: [21] | F23: Nassar et al. 2012. Criticality of the Geological Copper Family
C24: Silver
C25: Strontium
C26: Sulfur
C27: Tellurium
C28: Vanadium
C29: Yttrium
C30: Zirconium

Sheet Framework Data
A1: Production and Demand Values
B3: in t/a | C3: Reference | D3: 1990 | E3: 1991 | F3: 1992 | G3: 1993 | H3: 1994 | I3: 1995 | J3: 1996 | K3: 1997 | L3: 1998 | M3: 1999 | N3: 2000 | O3: 2001 | P3: 2002 | Q3: 2003 | R3: 2004 | S3: 2005 | T3: 2006 | U3: 2007 | V3: 2008 | W3: 2009 | X3: 2010 | Y3: 2011 | Z3: 2012 | AA3: 2013 | AB3: 2014 | AC3: 2015 | AD3: 2016 | AE3: 2017 | AF3: 2018 | AG3: 2019
A4: Cadmium | B4: Production | C4: [1] | H4: 18100 | I4: 18500 | J4: 18900 | K4: 20000 | L4: 19600 | M4: 19100 | N4: 19700 | O4: 18200 | P4: 15800 | Q4: 16900 | R4: 18800 | S4: 19400 | T4: 19300 | U4: 20400 | V4: 19600 | W4: 18800 | X4: 21100 | Y4: 22200 | Z4: 20900 | AA4: 22000 | AB4: 22400 | AC4: 23200 | AD4: 23900 | AE4: 25400 | AF4: 25100 | AG4: 25000
B5: Demand Energy Sector | D5: ='Data_Demand-Energy-Sector'!D29 -> 0 | E5: ='Data_Demand-Energy-Sector'!E29 -> 19.490674 | F5: ='Data_Demand-Energy-Sector'!F29 -> 19.490674 | G5: ='Data_Demand-Energy-Sector'!G29 -> 19.490674 | H5: ='Data_Demand-Energy-Sector'!H29 -> 19.490674 | I5: ='Data_Demand-Energy-Sector'!I29 -> 19.490674 | J5: ='Data_Demand-Energy-Sector'!J29 -> 19.490674 | K5: ='Data_Demand-Energy-Sector'!K29 -> 19.490674 | ... AG5: ='Data_Demand-Energy-Sector'!AG29 -> 127.15312
A6: Cerium | B6: Demand Energy Sector | D6: ='Data_Demand-Energy-Sector'!D34 -> 0 | E6: ='Data_Demand-Energy-Sector'!E34 -> 9.7699912e-08 | F6: ='Data_Demand-Energy-Sector'!F34 -> 9.7699912e-08 | G6: ='Data_Demand-Energy-Sector'!G34 -> 9.7699912e-08 | H6: ='Data_Demand-Energy-Sector'!H34 -> 9.7699912e-08 | I6: ='Data_Demand-Energy-Sector'!I34 -> 9.7699912e-08 | J6: ='Data_Demand-Energy-Sector'!J34 -> 9.7699912e-08 | K6: ='Data_Demand-Energy-Sector'!K34 -> 9.7699912e-08 | ... AG6: ='Data_Demand-Energy-Sector'!AG34 -> 0.080765855
A7: Cobalt | B7: Production | C7: [1] | H7: 18500 | I7: 22100 | J7: 27000 | K7: 27000 | L7: 26300 | M7: 29900 | N7: 33300 | O7: 36700 | P7: 47600 | Q7: 48400 | R7: 52400 | S7: 57900 | T7: 67500 | U7: 65500 | V7: 75900 | W7: 72300 | X7: 89500 | Y7: 109000 | Z7: 103000 | AA7: 110000 | AB7: 123000 | AC7: 126000 | AD7: 111000 | AE7: 120000 | AF7: 148000 | AG7: 140000
B8: Demand Energy Sector | D8: ='Data_Demand-Energy-Sector'!D51 -> 0 | E8: ='Data_Demand-Energy-Sector'!E51 -> 523.49608 | F8: ='Data_Demand-Energy-Sector'!F51 -> 523.49608 | G8: ='Data_Demand-Energy-Sector'!G51 -> 523.49608 | H8: ='Data_Demand-Energy-Sector'!H51 -> 523.49608 | I8: ='Data_Demand-Energy-Sector'!I51 -> 523.49608 | J8: ='Data_Demand-Energy-Sector'!J51 -> 523.49608 | K8: ='Data_Demand-Energy-Sector'!K51 -> 523.49608 | ... AG8: ='Data_Demand-Energy-Sector'!AG51 -> 24883.839
A9: Dysprosium | B9: Demand Energy Sector | D9: ='Data_Demand-Energy-Sector'!D64 -> 0 | E9: ='Data_Demand-Energy-Sector'!E64 -> 0 | F9: ='Data_Demand-Energy-Sector'!F64 -> 0 | G9: ='Data_Demand-Energy-Sector'!G64 -> 0 | H9: ='Data_Demand-Energy-Sector'!H64 -> 0 | I9: ='Data_Demand-Energy-Sector'!I64 -> 0 | J9: ='Data_Demand-Energy-Sector'!J64 -> 0 | K9: ='Data_Demand-Energy-Sector'!K64 -> 0 | ... AG9: ='Data_Demand-Energy-Sector'!AG64 -> 670.17444
A10: Gadolinium | B10: Demand Energy Sector | D10: ='Data_Demand-Energy-Sector'!D69 -> 0 | E10: ='Data_Demand-Energy-Sector'!E69 -> 2.1527099e-08 | F10: ='Data_Demand-Energy-Sector'!F69 -> 2.1527099e-08 | G10: ='Data_Demand-Energy-Sector'!G69 -> 2.1527099e-08 | H10: ='Data_Demand-Energy-Sector'!H69 -> 2.1527099e-08 | I10: ='Data_Demand-Energy-Sector'!I69 -> 2.1527099e-08 | J10: ='Data_Demand-Energy-Sector'!J69 -> 2.1527099e-08 | K10: ='Data_Demand-Energy-Sector'!K69 -> 2.1527099e-08 | ... AG10: ='Data_Demand-Energy-Sector'!AG69 -> 0.012848215
A11: Gallium | B11: Production | C11: [1] | I11: 35 | J11: 63 | K11: 54 | L11: 60 | M11: 75 | N11: 100 | O11: 75 | P11: 61 | Q11: 64 | R11: 69 | S11: 63 | T11: 69 | U11: 80 | V11: 95 | W11: 79 | X11: 182 | Y11: 292 | Z11: 383 | AA11: 350 | AB11: 435 | AC11: 470 | AD11: 274 | AE11: 320 | AF11: 413 | AG11: 320
B12: Demand Energy Sector | D12: ='Data_Demand-Energy-Sector'!D72 -> 0 | E12: ='Data_Demand-Energy-Sector'!E72 -> 0.10111533 | F12: ='Data_Demand-Energy-Sector'!F72 -> 0.10111533 | G12: ='Data_Demand-Energy-Sector'!G72 -> 0.10111533 | H12: ='Data_Demand-Energy-Sector'!H72 -> 0.10111533 | I12: ='Data_Demand-Energy-Sector'!I72 -> 0.10111533 | J12: ='Data_Demand-Energy-Sector'!J72 -> 0.10111533 | K12: ='Data_Demand-Energy-Sector'!K72 -> 0.10111533 | ... AG12: ='Data_Demand-Energy-Sector'!AG72 -> 11.590304
A13: Germanium | B13: Production | C13: [1] | H13: 50 | I13: 45 | J13: 53 | K13: 63 | L13: 56 | M13: 58 | N13: 71 | O13: 68 | P13: 50 | Q13: 44 | R13: 87 | S13: 90 | T13: 90 | U13: 100 | V13: 140 | W13: 120 | X13: 118 | Y13: 118 | Z13: 150 | AA13: 155 | AB13: 165 | AC13: 160 | AD13: 126 | AE13: 106 | AF13: 130 | AG13: 130
B14: Demand Energy Sector | D14: ='Data_Demand-Energy-Sector'!D75 -> 0 | E14: ='Data_Demand-Energy-Sector'!E75 -> 1.8508816 | F14: ='Data_Demand-Energy-Sector'!F75 -> 1.8508816 | G14: ='Data_Demand-Energy-Sector'!G75 -> 1.8508816 | H14: ='Data_Demand-Energy-Sector'!H75 -> 1.8508816 | I14: ='Data_Demand-Energy-Sector'!I75 -> 1.8508816 | J14: ='Data_Demand-Energy-Sector'!J75 -> 1.8508816 | K14: ='Data_Demand-Energy-Sector'!K75 -> 1.8508816 | ... AG14: ='Data_Demand-Energy-Sector'!AG75 -> 45.310701
A15: Indium | B15: Production | C15: [1] | H15: 145 | I15: 239 | J15: 200 | K15: 230 | L15: 230 | M15: 215 | N15: 335 | O15: 345 | P15: 335 | Q15: 370 | R15: 405 | S15: 500 | T15: 580 | U15: 563 | V15: 570 | W15: 546 | X15: 609 | Y15: 662 | Z15: 782 | AA15: 799 | AB15: 844 | AC15: 759 | AD15: 680 | AE15: 714 | AF15: 741 | AG15: 760
B16: Demand Energy Sector | D16: ='Data_Demand-Energy-Sector'!D80 -> 0 | E16: ='Data_Demand-Energy-Sector'!E80 -> 47.077765 | F16: ='Data_Demand-Energy-Sector'!F80 -> 47.077765 | G16: ='Data_Demand-Energy-Sector'!G80 -> 47.077765 | H16: ='Data_Demand-Energy-Sector'!H80 -> 47.077765 | I16: ='Data_Demand-Energy-Sector'!I80 -> 47.077765 | J16: ='Data_Demand-Energy-Sector'!J80 -> 47.077765 | K16: ='Data_Demand-Energy-Sector'!K80 -> 47.077765 | ... AG16: ='Data_Demand-Energy-Sector'!AG80 -> 89.311567
A17: Iridium | B17: Production PGM | C17: [2] | D17: 291 | E17: 288 | F17: 282 | G17: 275 | H17: 269 | I17: 287 | J17: 283 | K17: 281 | L17: 348 | M17: 376 | N17: 378 | O17: 408 | P17: 414 | Q17: 452 | R17: 492 | S17: 510 | T17: 513 | U17: 512 | V17: 460 | W17: 449 | X17: 466 | Y17: 487 | Z17: 423 | AA17: 455 | AB17: 391 | AC17: 478 | AD17: 467 | AE17: 489
B18: Total Demand | C18: [3, 4] | S18: 4 | T18: 4.1 | U18: 3.2 | V18: 3.2 | W18: 2.4 | X18: 10.6 | Y18: 10.4 | Z18: 6.1 | AA18: 5.9 | AB18: 5.9 | AC18: 6.9 | AD18: 7.8 | AE18: 7 | AF18: 6.8 | AG18: 8.2
B19: Demand Energy Sector | D19: ='Data_Demand-Energy-Sector'!D83 -> 0 | E19: ='Data_Demand-Energy-Sector'!E83 -> 0 | F19: ='Data_Demand-Energy-Sector'!F83 -> 0 | G19: ='Data_Demand-Energy-Sector'!G83 -> 0 | H19: ='Data_Demand-Energy-Sector'!H83 -> 0 | I19: ='Data_Demand-Energy-Sector'!I83 -> 0 | J19: ='Data_Demand-Energy-Sector'!J83 -> 0 | K19: ='Data_Demand-Energy-Sector'!K83 -> 0 | ... AG19: ='Data_Demand-Energy-Sector'!AG83 -> 0.30336703
A20: Lanthanum | B20: Demand Energy Sector | D20: ='Data_Demand-Energy-Sector'!D90 -> 0 | E20: ='Data_Demand-Energy-Sector'!E90 -> 4.0404709e-07 | F20: ='Data_Demand-Energy-Sector'!F90 -> 4.0404709e-07 | G20: ='Data_Demand-Energy-Sector'!G90 -> 4.0404709e-07 | H20: ='Data_Demand-Energy-Sector'!H90 -> 4.0404709e-07 | I20: ='Data_Demand-Energy-Sector'!I90 -> 4.0404709e-07 | J20: ='Data_Demand-Energy-Sector'!J90 -> 4.0404709e-07 | K20: ='Data_Demand-Energy-Sector'!K90 -> 4.0404709e-07 | ... AG20: ='Data_Demand-Energy-Sector'!AG90 -> 0.32992019
A21: Lithium | B21: Production | C21: [1] | H21: 6100 | I21: 6300 | J21: 11000 | K21: 14000 | L21: 15000 | M21: 14000 | N21: 14000 | O21: 15100 | P21: 14200 | Q21: 15100 | R21: 20200 | S21: 20600 | T21: 23500 | U21: 25800 | V21: 25400 | W21: 18800 | X21: 28100 | Y21: 34100 | Z21: 35000 | AA21: 34000 | AB21: 31700 | AC21: 31500 | AD21: 38000 | AE21: 69000 | AF21: 95000 | AG21: 86000
B22: Demand Energy Sector | D22: ='Data_Demand-Energy-Sector'!D101 -> 0 | E22: ='Data_Demand-Energy-Sector'!E101 -> 373.933 | F22: ='Data_Demand-Energy-Sector'!F101 -> 373.933 | G22: ='Data_Demand-Energy-Sector'!G101 -> 373.933 | H22: ='Data_Demand-Energy-Sector'!H101 -> 373.933 | I22: ='Data_Demand-Energy-Sector'!I101 -> 373.933 | J22: ='Data_Demand-Energy-Sector'!J101 -> 373.933 | K22: ='Data_Demand-Energy-Sector'!K101 -> 373.933 | ... AG22: ='Data_Demand-Energy-Sector'!AG101 -> 22672.341
A23: Manganese | B23: Production | C23: [1] | H23: 7190000 | I23: 7580000 | J23: 7730000 | K23: 7680000 | L23: 7040000 | M23: 6990000 | N23: 7280000 | O23: 7600000 | P23: 8100000 | Q23: 8200000 | R23: 9350000 | S23: 10500000 | T23: 11900000 | U23: 12600000 | V23: 13300000 | W23: 10800000 | X23: 13900000 | Y23: 16000000 | Z23: 15800000 | AA23: 16900000 | AB23: 17800000 | AC23: 17500000 | AD23: 15700000 | AE23: 17300000 | AF23: 18900000 | AG23: 19000000
B24: Demand Energy Sector | D24: ='Data_Demand-Energy-Sector'!D128 -> 0 | E24: ='Data_Demand-Energy-Sector'!E128 -> 5085.0915 | F24: ='Data_Demand-Energy-Sector'!F128 -> 5085.0915 | G24: ='Data_Demand-Energy-Sector'!G128 -> 5085.0915 | H24: ='Data_Demand-Energy-Sector'!H128 -> 5085.0915 | I24: ='Data_Demand-Energy-Sector'!I128 -> 5085.0915 | J24: ='Data_Demand-Energy-Sector'!J128 -> 5085.0915 | K24: ='Data_Demand-Energy-Sector'!K128 -> 5085.0915 | ... AG24: ='Data_Demand-Energy-Sector'!AG128 -> 129237.62
A25: Neodymium | B25: Demand Energy Sector | D25: ='Data_Demand-Energy-Sector'!D141 -> 0 | E25: ='Data_Demand-Energy-Sector'!E141 -> 0 | F25: ='Data_Demand-Energy-Sector'!F141 -> 0 | G25: ='Data_Demand-Energy-Sector'!G141 -> 0 | H25: ='Data_Demand-Energy-Sector'!H141 -> 0 | I25: ='Data_Demand-Energy-Sector'!I141 -> 0 | J25: ='Data_Demand-Energy-Sector'!J141 -> 0 | K25: ='Data_Demand-Energy-Sector'!K141 -> 0 | ... AG25: ='Data_Demand-Energy-Sector'!AG141 -> 1838.3601
A26: Nickel | B26: Production | C26: [1] | H26: 906000 | I26: 1040000 | J26: 1080000 | K26: 1120000 | L26: 1140000 | M26: 1120000 | N26: 1250000 | O26: 1330000 | P26: 1340000 | Q26: 1400000 | R26: 1400000 | S26: 1490000 | T26: 1580000 | U26: 1660000 | V26: 1570000 | W26: 1400000 | X26: 1590000 | Y26: 1940000 | Z26: 2220000 | AA26: 2630000 | AB26: 2450000 | AC26: 2280000 | AD26: 2090000 | AE26: 2160000 | AF26: 2400000 | AG26: 2700000
B27: Demand Energy Sector | D27: ='Data_Demand-Energy-Sector'!D172 -> 0 | E27: ='Data_Demand-Energy-Sector'!E172 -> 25521.964 | F27: ='Data_Demand-Energy-Sector'!F172 -> 25521.964 | G27: ='Data_Demand-Energy-Sector'!G172 -> 25521.964 | H27: ='Data_Demand-Energy-Sector'!H172 -> 25521.964 | I27: ='Data_Demand-Energy-Sector'!I172 -> 25521.964 | J27: ='Data_Demand-Energy-Sector'!J172 -> 25521.964 | K27: ='Data_Demand-Energy-Sector'!K172 -> 25521.964 | ... AG27: ='Data_Demand-Energy-Sector'!AG172 -> 91022.324
A28: Platinum | B28: Production | C28: [1] | H28: 128 | I28: 145 | J28: 146 | K28: 154 | L28: 146 | M28: 169 | N28: 155 | O28: 160 | P28: 184 | Q28: 205 | R28: 214 | S28: 217 | T28: 221 | U28: 213 | V28: 189 | W28: 181 | X28: 192 | Y28: 195 | Z28: 183 | AA28: 183 | AB28: 147 | AC28: 189 | AD28: 191 | AE28: 199 | AF28: 190 | AG28: 180
B29: Demand Energy Sector | D29: ='Data_Demand-Energy-Sector'!D179 -> 0 | E29: ='Data_Demand-Energy-Sector'!E179 -> 2.1297587e-07 | F29: ='Data_Demand-Energy-Sector'!F179 -> 2.1297587e-07 | G29: ='Data_Demand-Energy-Sector'!G179 -> 2.1297587e-07 | H29: ='Data_Demand-Energy-Sector'!H179 -> 2.1297587e-07 | I29: ='Data_Demand-Energy-Sector'!I179 -> 2.1297587e-07 | J29: ='Data_Demand-Energy-Sector'!J179 -> 2.1297587e-07 | K29: ='Data_Demand-Energy-Sector'!K179 -> 2.1297587e-07 | ... AG29: ='Data_Demand-Energy-Sector'!AG179 -> 0.16974883
A30: Potassium | B30: Production | C30: [1] | H30: 18675000 | I30: 20169000 | J30: 19256000 | K30: 21331000 | L30: 20833000 | M30: 21331000 | N30: 20999000 | O30: 21912000 | P30: 21829000 | Q30: 23572000 | R30: 23987000 | S30: 25813000 | T30: 24153000 | U30: 28723000 | V30: 29055000 | W30: 17264000 | X30: 27971000 | Y30: 30212000 | Z30: 27141000 | AA30: 28635000 | AB30: 32204000 | AC30: 33781000 | AD30: 32619000 | AE30: 34362000 | AF30: 35945000 | AG30: 34000000
B31: Demand Energy Sector | D31: ='Data_Demand-Energy-Sector'!D188 -> 0 | E31: ='Data_Demand-Energy-Sector'!E188 -> 0.00055430174 | F31: ='Data_Demand-Energy-Sector'!F188 -> 0.00055430174 | G31: ='Data_Demand-Energy-Sector'!G188 -> 0.00055430174 | H31: ='Data_Demand-Energy-Sector'!H188 -> 0.00055430174 | I31: ='Data_Demand-Energy-Sector'!I188 -> 0.00055430174 | J31: ='Data_Demand-Energy-Sector'!J188 -> 0.00055430174 | K31: ='Data_Demand-Energy-Sector'!K188 -> 0.00055430174 | ... AG31: ='Data_Demand-Energy-Sector'!AG188 -> 132026.37
A32: REE | B32: Production | C32: [1] | H32: 64500 | I32: 79900 | J32: 84800 | K32: 79700 | L32: 76600 | M32: 82000 | N32: 83500 | O32: 83500 | P32: 98300 | Q32: 99100 | R32: 102000 | S32: 123000 | T32: 123000 | U32: 124000 | V32: 124000 | W32: 133000 | X32: 133000 | Y32: 111000 | Z32: 110000 | AA32: 110000 | AB32: 123000 | AC32: 130000 | AD32: 129000 | AE32: 132000 | AF32: 190000 | AG32: 210000
A33: Scandium | B33: Production | C33: [1] | H33: 3.8 | AA33: 6.5 | AC33: 8.1 | AD33: 8.1 | AE33: 8.1 | AG33: 11.41
B34: Demand Energy Sector | D34: ='Data_Demand-Energy-Sector'!D195 -> 0 | E34: ='Data_Demand-Energy-Sector'!E195 -> 3.8086406e-08 | F34: ='Data_Demand-Energy-Sector'!F195 -> 3.8086406e-08 | G34: ='Data_Demand-Energy-Sector'!G195 -> 3.8086406e-08 | H34: ='Data_Demand-Energy-Sector'!H195 -> 3.8086406e-08 | I34: ='Data_Demand-Energy-Sector'!I195 -> 3.8086406e-08 | J34: ='Data_Demand-Energy-Sector'!J195 -> 3.8086406e-08 | K34: ='Data_Demand-Energy-Sector'!K195 -> 3.8086406e-08 | ... AG34: ='Data_Demand-Energy-Sector'!AG195 -> 0.022731457
A35: Selenium | B35: Production | C35: [1] | H35: 1880 | I35: 2070 | J35: 2150 | K35: 1640 | L35: 1450 | M35: 1480 | N35: 1410 | O35: 1580 | P35: 1510 | Q35: 1430 | R35: 1330 | S35: 1390 | T35: 1540 | U35: 1560 | V35: 1510 | W35: 2280 | X35: 2120 | Y35: 1980 | Z35: 2000 | AA35: 2334 | AB35: 2310 | AC35: 2200 | AD35: 3270 | AE35: 2710 | AF35: 2810 | AG35: 2800
B36: Demand Energy Sector | D36: ='Data_Demand-Energy-Sector'!D198 -> 0 | E36: ='Data_Demand-Energy-Sector'!E198 -> 0.13945703 | F36: ='Data_Demand-Energy-Sector'!F198 -> 0.13945703 | G36: ='Data_Demand-Energy-Sector'!G198 -> 0.13945703 | H36: ='Data_Demand-Energy-Sector'!H198 -> 0.13945703 | I36: ='Data_Demand-Energy-Sector'!I198 -> 0.13945703 | J36: ='Data_Demand-Energy-Sector'!J198 -> 0.13945703 | K36: ='Data_Demand-Energy-Sector'!K198 -> 0.13945703 | ... AG36: ='Data_Demand-Energy-Sector'!AG198 -> 100.78355
A37: Silver | B37: Production | C37: [1] | H37: 13900 | I37: 14600 | J37: 15200 | K37: 16400 | L37: 16400 | M37: 17700 | N37: 17700 | O37: 18700 | P37: 20000 | Q37: 18800 | R37: 19700 | S37: 19300 | T37: 20200 | U37: 20800 | V37: 21300 | W37: 21800 | X37: 23100 | Y37: 23300 | Z37: 25500 | AA37: 26000 | AB37: 26800 | AC37: 25100 | AD37: 25700 | AE37: 26800 | AF37: 26900 | AG37: 27000
B38: Demand Energy Sector | D38: ='Data_Demand-Energy-Sector'!D205 -> 0 | E38: ='Data_Demand-Energy-Sector'!E205 -> 222.26012 | F38: ='Data_Demand-Energy-Sector'!F205 -> 222.26012 | G38: ='Data_Demand-Energy-Sector'!G205 -> 222.26012 | H38: ='Data_Demand-Energy-Sector'!H205 -> 222.26012 | I38: ='Data_Demand-Energy-Sector'!I205 -> 222.26012 | J38: ='Data_Demand-Energy-Sector'!J205 -> 222.26012 | K38: ='Data_Demand-Energy-Sector'!K205 -> 222.26012 | ... AG38: ='Data_Demand-Energy-Sector'!AG205 -> 2622.0875
A39: Strontium | B39: Production | C39: [1] | H39: 180000 | I39: 170000 | J39: 330000 | K39: 340000 | L39: 311000 | M39: 304000 | N39: 520000 | O39: 370000 | P39: 390000 | Q39: 470000 | R39: 551000 | S39: 494000 | T39: 585000 | U39: 511000 | V39: 496000 | W39: 402000 | X39: 405000 | Y39: 375000 | Z39: 228000 | AA39: 333000 | AB39: 343000 | AC39: 354000 | AD39: 202000 | AE39: 255000 | AF39: 220000 | AG39: 220000
B40: Demand Energy Sector | D40: ='Data_Demand-Energy-Sector'!D212 -> 0 | E40: ='Data_Demand-Energy-Sector'!E212 -> 5.5804865e-08 | F40: ='Data_Demand-Energy-Sector'!F212 -> 5.5804865e-08 | G40: ='Data_Demand-Energy-Sector'!G212 -> 5.5804865e-08 | H40: ='Data_Demand-Energy-Sector'!H212 -> 5.5804865e-08 | I40: ='Data_Demand-Energy-Sector'!I212 -> 5.5804865e-08 | J40: ='Data_Demand-Energy-Sector'!J212 -> 5.5804865e-08 | K40: ='Data_Demand-Energy-Sector'!K212 -> 5.5804865e-08 | ... AG40: ='Data_Demand-Energy-Sector'!AG212 -> 0.033306526
A41: Sulfur | B41: Production | C41: [1] | H41: 51000000 | I41: 54300000 | J41: 52400000 | K41: 53600000 | L41: 57800000 | M41: 57100000 | N41: 57200000 | O41: 57300000 | P41: 57700000 | Q41: 61800000 | R41: 64100000 | S41: 66000000 | T41: 65700000 | U41: 68400000 | V41: 69600000 | W41: 67900000 | X41: 68100000 | Y41: 70500000 | Z41: 68100000 | AA41: 70400000 | AB41: 70000000 | AC41: 69400000 | AD41: 83000000 | AE41: 80200000 | AF41: 79400000 | AG41: 79000000
...

Sheet Data_Demand-Energy-Sector
A1: Correction Factor (Standard 1, if changes are necessary please comment reason)
C2: Sub Sector | D2: Factor | E2: Comment
C3: BEV - batt | D3: =D4 -> 0.4
C4: BEV - PM | D4: 0.4 | E4: Number of EV's in scenario does not match real fleet numbers
C5: CSP | D5: 1
C6: Electrolysers | D6: 1
C7: FCEV - batt | D7: =D8 -> 0.0056
C8: FCEV - PM | D8: 0.0056 | E8: Number of FCEV's in scenario does not match real fleet numbers
C9: Fossil PP | D9: 1
C10: H2 FC | D10: 1
C11: H2 FC - trans | D11: =D8 -> 0.0056
C12: HEV - batt | D12: =D$4 -> 0.4
C13: HEV - PM | D13: =D$4 -> 0.4
C14: Nuclear | D14: 1
C15: Other RES PP | D15: 1
C16: PHEV - batt | D16: =D$4 -> 0.4
C17: PHEV - PM | D17: =D$4 -> 0.4
C18: PV | D18: 1
C19: Stat. Batteries | D19: 1
C20: Wind offshore | D20: 1
C21: Wind onshore | D21: 1
A23: Cumulative Resource Demand in the Energy Sector (LDF CONT/MEAN)
A24: Resource | C24: Sub-Sector | D24: 1990 | E24: 1991 | F24: 1992 | G24: 1993 | H24: 1994 | I24: 1995 | J24: 1996 | K24: 1997 | L24: 1998 | M24: 1999 | N24: 2000 | O24: 2001 | P24: 2002 | Q24: 2003 | R24: 2004 | S24: 2005 | T24: 2006 | U24: 2007 | V24: 2008 | W24: 2009 | X24: 2010 | Y24: 2011 | Z24: 2012 | AA24: 2013 | AB24: 2014 | AC24: 2015 | AD24: 2016 | AE24: 2017 | AF24: 2018 | AG24: 2019
A25: Cadmium | B25: Raw Data | C25: Nuclear | D25: 0 | E25: 19.487223 | F25: 19.487223 | G25: 19.487223 | H25: 19.487223 | I25: 19.487223 | J25: 19.487223 | K25: 19.487223 | L25: 19.487223 | M25: 19.487223 | N25: 19.487223 | O25: 19.487223 | P25: 19.487223 | Q25: 19.487223 | R25: 19.487223 | S25: 19.487223 | T25: 0 | U25: 0 | V25: 0 | W25: 0 | X25: 7.8015742 | Y25: 0 | Z25: 0 | AA25: 0.20063954 | AB25: 0.53410312 | AC25: 0.76584346 | AD25: 3.0096842 | AE25: 5.9508815 | AF25: 6.8182398 | AG25: 5.6117591
C26: PV | D26: 0 | E26: 0.003451035 | F26: 0.003451035 | G26: 0.003451035 | H26: 0.003451035 | I26: 0.003451035 | J26: 0.003451035 | K26: 0.003451035 | L26: 0.003451035 | M26: 0.003451035 | N26: 0.003451035 | O26: 0 | P26: 0 | Q26: 0 | R26: 0.22805003 | S26: 0.22805003 | T26: 2.8512263 | U26: 11.351667 | V26: 32.223227 | W26: 84.029681 | X26: 79.493504 | Y26: 128.2769 | Z26: 149.72774 | AA26: 125.88447 | AB26: 151.07479 | AC26: 188.05143 | AD26: 198.10042 | AE26: 137.61699 | AF26: 131.72629 | AG26: 121.54136
B27: Corrected Data | C27: Nuclear | D27: =D25*$D14 -> 0 | E27: =E25*$D14 -> 19.487223 | F27: =F25*$D14 -> 19.487223 | G27: =G25*$D14 -> 19.487223 | H27: =H25*$D14 -> 19.487223 | I27: =I25*$D14 -> 19.487223 | J27: =J25*$D14 -> 19.487223 | K27: =K25*$D14 -> 19.487223 | ... AG27: =AG25*$D14 -> 5.6117591
C28: PV | D28: =D26*$D18 -> 0 | E28: =E26*$D18 -> 0.003451035 | F28: =F26*$D18 -> 0.003451035 | G28: =G26*$D18 -> 0.003451035 | H28: =H26*$D18 -> 0.003451035 | I28: =I26*$D18 -> 0.003451035 | J28: =J26*$D18 -> 0.003451035 | K28: =K26*$D18 -> 0.003451035 | ... AG28: =AG26*$D18 -> 121.54136
C29: Sum | D29: =SUM(D27:D28) -> 0 | E29: =SUM(E27:E28) -> 19.490674 | F29: =SUM(F27:F28) -> 19.490674 | G29: =SUM(G27:G28) -> 19.490674 | H29: =SUM(H27:H28) -> 19.490674 | I29: =SUM(I27:I28) -> 19.490674 | J29: =SUM(J27:J28) -> 19.490674 | K29: =SUM(K27:K28) -> 19.490674 | ... AG29: =SUM(AG27:AG28) -> 127.15312
A30: Cerium | B30: Raw Data | C30: H2 FC | D30: 0 | E30: 9.7699912e-08 | F30: 9.7699912e-08 | G30: 9.7699912e-08 | H30: 9.7699912e-08 | I30: 9.7699912e-08 | J30: 9.7699912e-08 | K30: 9.7699912e-08 | L30: 9.7699912e-08 | M30: 9.7699912e-08 | N30: 9.7699912e-08 | O30: 9.7699912e-08 | P30: 9.7699912e-08 | Q30: 9.7699912e-08 | R30: 9.7699912e-08 | S30: 9.7699912e-08 | T30: 2.4825812e-07 | U30: 2.7928279e-07 | V30: 2.8267855e-07 | W30: 3.1353207e-07 | X30: 1.1276587e-06 | Y30: 7.3768425e-07 | Z30: 9.3111239e-07 | AA30: 4.5960774e-07 | AB30: 4.3365723e-07 | AC30: 4.834266e-07 | AD30: 0.012430989 | AE30: 0.046632638 | AF30: 0.074357932 | AG30: 0.080765855
C31: H2 FC - trans | D31: 0 | E31: 0 | F31: 0 | G31: 0 | H31: 0 | I31: 0 | J31: 0 | K31: 0 | L31: 0 | M31: 0 | N31: 0 | O31: 0 | P31: 0 | Q31: 0 | R31: 0 | S31: 0 | T31: 0 | U31: 0 | V31: 0 | W31: 0 | X31: 0 | Y31: 0 | Z31: 0 | AA31: 0 | AB31: 0 | AC31: 0 | AD31: 0 | AE31: 0 | AF31: 0 | AG31: 0
B32: Corrected Data | C32: H2 FC | D32: =D30*$D10 -> 0 | E32: =E30*$D10 -> 9.7699912e-08 | F32: =F30*$D10 -> 9.7699912e-08 | G32: =G30*$D10 -> 9.7699912e-08 | H32: =H30*$D10 -> 9.7699912e-08 | I32: =I30*$D10 -> 9.7699912e-08 | J32: =J30*$D10 -> 9.7699912e-08 | K32: =K30*$D10 -> 9.7699912e-08 | ... AG32: =AG30*$D10 -> 0.080765855
C33: H2 FC - trans | D33: =D31*$D11 -> 0 | E33: =E31*$D11 -> 0 | F33: =F31*$D11 -> 0 | G33: =G31*$D11 -> 0 | H33: =H31*$D11 -> 0 | I33: =I31*$D11 -> 0 | J33: =J31*$D11 -> 0 | K33: =K31*$D11 -> 0 | ... AG33: =AG31*$D11 -> 0
C34: Sum | D34: =SUM(D32) -> 0 | E34: =SUM(E32) -> 9.7699912e-08 | F34: =SUM(F32) -> 9.7699912e-08 | G34: =SUM(G32) -> 9.7699912e-08 | H34: =SUM(H32) -> 9.7699912e-08 | I34: =SUM(I32) -> 9.7699912e-08 | J34: =SUM(J32) -> 9.7699912e-08 | K34: =SUM(K32) -> 9.7699912e-08 | ... AG34: =SUM(AG32) -> 0.080765855
A35: Cobalt | B35: Raw Data | C35: BEV - batt | D35: 0 | E35: 0 | F35: 0 | G35: 0 | H35: 0 | I35: 0 | J35: 0 | K35: 0 | L35: 0 | M35: 0 | N35: 0 | O35: 0 | P35: 0 | Q35: 0 | R35: 0 | S35: 0 | T35: 7199.5586 | U35: 11999.264 | V35: 9599.4115 | W35: 9599.4115 | X35: 9599.4115 | Y35: 7559.6241 | Z35: 7670.5521 | AA35: 6921.8131 | AB35: 14104.804 | AC35: 20973.29 | AD35: 27132.336 | AE35: 39662.734 | AF35: 50877.97 | AG35: 57072.991
C36: Electrolysers | D36: 0 | E36: 5.9552915e-06 | F36: 5.9552915e-06 | G36: 5.9552915e-06 | H36: 5.9552915e-06 | I36: 5.9552915e-06 | J36: 5.9552915e-06 | K36: 5.9552915e-06 | L36: 5.9552915e-06 | M36: 5.9552915e-06 | N36: 5.9552915e-06 | O36: 5.8957386e-06 | P36: 5.8361857e-06 | Q36: 5.7766328e-06 | R36: 5.7170798e-06 | S36: 5.6575269e-06 | T36: 1.4609974e-05 | U36: 1.6494036e-05 | V36: 1.6699852e-05 | W36: 1.8299983e-05 | X36: 2.2082123e-05 | Y36: 2.4502486e-05 | Z36: 1.5859871e-05 | AA36: 3.8754799e-06 | AB36: 3.0508702e-06 | AC36: 3.4779948e-06 | AD36: 0.5228789 | AE36: 1.4603197 | AF36: 2.2541318 | AG36: 2.9081591
C37: FCEV - batt | D37: 0 | E37: 0 | F37: 0 | G37: 0 | H37: 0 | I37: 0 | J37: 0 | K37: 0 | L37: 0 | M37: 0 | N37: 0 | O37: 0 | P37: 0 | Q37: 0 | R37: 0 | S37: 0 | T37: 6.6129124e-08 | U37: 1.1021521e-07 | V37: 8.8172165e-08 | W37: 8.8172165e-08 | X37: 8.8172165e-08 | Y37: 0 | Z37: 0 | AA37: 0 | AB37: 0 | AC37: 0 | AD37: 133.19495 | AE37: 387.20595 | AF37: 620.73915 | AG37: 832.56472
C38: H2 FC | D38: 0 | E38: 9.9355843e-08 | F38: 9.9355843e-08 | G38: 9.9355843e-08 | H38: 9.9355843e-08 | I38: 9.9355843e-08 | J38: 9.9355843e-08 | K38: 9.9355843e-08 | L38: 9.9355843e-08 | M38: 9.9355843e-08 | N38: 9.9355843e-08 | O38: 9.9355843e-08 | P38: 9.9355843e-08 | Q38: 9.9355843e-08 | R38: 9.9355843e-08 | S38: 9.9355843e-08 | T38: 2.5246589e-07 | U38: 2.8401639e-07 | V38: 2.8746971e-07 | W38: 3.1884617e-07 | X38: 3.3829762e-06 | Y38: 2.6824882e-06 | Z38: 2.981652e-06 | AA38: 1.2586768e-06 | AB38: 1.2213204e-06 | AC38: 1.4672091e-06 | AD38: 0.036154049 | AE38: 0.12152149 | AF38: 0.17777715 | AG38: 0.2024088
C39: H2 FC - trans | D39: 0 | E39: 0 | F39: 0 | G39: 0 | H39: 0 | I39: 0 | J39: 0 | K39: 0 | L39: 0 | M39: 0 | N39: 0 | O39: 0 | P39: 0 | Q39: 0 | R39: 0 | S39: 0 | T39: 0 | U39: 0 | V39: 0 | W39: 0 | X39: 0 | Y39: 0 | Z39: 0 | AA39: 0 | AB39: 0 | AC39: 0 | AD39: 0 | AE39: 0 | AF39: 0 | AG39: 0
C40: HEV - batt | D40: 0 | E40: 0 | F40: 0 | G40: 0 | H40: 0 | I40: 0 | J40: 0 | K40: 0 | L40: 0 | M40: 0 | N40: 0 | O40: 0 | P40: 0 | Q40: 0 | R40: 0 | S40: 0 | T40: 1.7523112e-08 | U40: 2.9205186e-08 | V40: 2.3364149e-08 | W40: 2.3364149e-08 | X40: 2.3364149e-08 | Y40: 0 | Z40: 0 | AA40: 0 | AB40: 0 | AC40: 0 | AD40: 1.7772512e-08 | AE40: 3.0029805e-08 | AF40: 2.4345632e-08 | AG40: 2.4662047e-08
C41: PHEV - batt | D41: 0 | E41: 0 | F41: 0 | G41: 0 | H41: 0 | I41: 0 | J41: 0 | K41: 0 | L41: 0 | M41: 0 | N41: 0 | O41: 0 | P41: 0 | Q41: 0 | R41: 0 | S41: 0 | T41: 0.42749115 | U41: 0.71248525 | V41: 0.5699882 | W41: 0.5699882 | X41: 0.5699882 | Y41: 53.310827 | Z41: 88.171774 | AA41: 58.330567 | AB41: 58.330567 | AC41: 95.562767 | AD41: 573.02327 | AE41: 1423.4678 | AF41: 2207.101 | AG41: 2920.4792
...

Sheet Data Non-Energy-Sector
A1: Demand in Non-Energy Sectors
A3: Resource | B3: Subsectors | C3: NACE-Code 4 digits | D3: NACE-Code 3-digits | E3: Share | F3: Reference | G3: Lifetime | H3: Reference | I3: Recycling | M3: Reference | N3: Comment
I4: 2020 | J4: 1990 | K4: mod 2050 | L4: amb 2050
A5: Cadmium | B5: Batteries | C5: C2720 | D5: C272 - Manufacture of batteries and accumulators | E5: 0.8 | F5: [9] | G5: =G57 -> 5 | H5: own assumption based on 'Lithium - Batteries' | I5: 0.15 | J5: 0 | K5: 0.15 | L5: 0.8 | M5: [8]
B6: Pigments | C6: C2030 | D6: C203 - Manufacture of paints, varnishes and similar coatings, printing ink and mastics | E6: 0.11 | G6: =G22 -> 1 | H6: own assumption based on 'Cobalt - Tyre adhesives and paint dryers' | I6: 0 | J6: 0 | K6: 0 | L6: 0 | N6: no Recycling (Selenium - Pigments)
B7: Coatings | C7: C2561 | D7: C256 - Treatment and coating of metals; machining | E7: 0.07 | G7: =G107 -> 15 | H7: own assumption based on 'Silver - parts like bearings' | I7: =I5 -> 0.15 | J7: 0 | K7: 0.15 | L7: 0.8
B8: Stabilisers | C8: C2059 | D8: C205 - Manufacture of other chemical products | E8: 0.02 | G8: =G59 -> 2 | H8: own assumption based on 'Lithium - Lubricants' | I8: =I5 -> 0.15 | J8: 0 | K8: 0.15 | L8: 0.8
A9: Cerium | B9: Autocatalyst | C9: C2932 | D9: C293 - Manufacture of parts and accessories for motor vehicles | E9: 0.35 | F9: [13] | G9: 12 | H9: own assumption | I9: 0.01 | J9: 0 | K9: 0.01 | L9: 0.8 | M9: [8]
B10: Glass & Ceramics | C10: C2310 | D10: C231 - Manufacture of glass and glass products | E10: 0.33 | G10: =G58 -> 8 | H10: own assumption based on 'Lithium - Glass & Ceramics' | I10: 0 | J10: 0 | K10: 0 | L10: 0 | N10: no Recycling (Lithium - Glass & Ceramics)
B11: Polishing Powders | C11: C2670 | D11: C267 - Manufacture of optical instruments and photographic equipment | E11: 0.11 | G11: 1 | H11: own assumption | I11: 0.01 | J11: 0 | K11: 0.01 | L11: 0.8
B12: Fluid Cracking Catalysts | C12: C1920 | D12: C192 - Manufacture of refined petroleum products | E12: 0.08 | G12: 2 | H12: [15] | I12: =I$11 -> 0.01 | J12: 0 | K12: 0.01 | L12: 0.8
B13: Metal | C13: C2410 | D13: C241 - Manufacture of basic iron and steel and of ferro-alloys | E13: 0.06 | G13: =G44 -> 13 | H13: own assumption based on 'Indium - Alloys/Compounds' | I13: =I$11 -> 0.01 | J13: 0 | K13: 0.01 | L13: 0.8
B14: Batteries | C14: C2720 | D14: C272 - Manufacture of batteries and accumulators | E14: 0.06 | G14: =G57 -> 5 | H14: own assumption based on 'Lithium - Batteries' | I14: =I$11 -> 0.01 | J14: 0 | K14: 0.01 | L14: 0.8
B15: Lighting | C15: C2740 | D15: C274 - Manufacture of electric lighting equipment | E15: 0.01 | G15: 6 | H15: [16] | I15: =I$11 -> 0.01 | J15: 0 | K15: 0.01 | L15: 0.8
A16: Cobalt | B16: Batteries | C16: C2720 | D16: C272 - Manufacture of batteries and accumulators | E16: 0.42 | F16: [13] | G16: 5 | H16: [17] | I16: 0.68 | J16: 0 | K16: 0.68 | L16: 0.8 | M16: [8]
B17: Superlloys, hardfacing/HSS and other alloy | C17: C2511/50/61/7 | D17: C25X - Manufacture of fabricated metal products, except machinery and equipment | E17: 0.23 | G17: 1 | H17: [15] | I17: =I$16 -> 0.68 | J17: 0 | K17: 0.68 | L17: 0.8
B18: Hard materials (carbides and diamond tools) | C18: C2573 | D18: C257 - Manufacture of cutlery, tools and general hardware | E18: 0.1 | G18: 1 | H18: [15] | I18: =I$16 -> 0.68 | J18: 0 | K18: 0.68 | L18: 0.8
B19: Catalysts | C19: C2013/59 | D19: C20X - Manufacture of chemicals and chemical products | E19: 0.07 | G19: 6 | H19: [15] | I19: =I$16 -> 0.68 | J19: 0 | K19: 0.68 | L19: 0.8
B20: Ceramic & Pigments | C20: C2012 | D20: C201 - Manufacture of basic chemicals, fertilisers and nitrogen compounds, plastics and synthetic rubber in primary forms | E20: 0.05 | G20: 1 | H20: [15] | I20: 0 | J20: 0 | K20: 0 | L20: 0 | N20: no Recycling (Zirconium - Ceramics)
B21: Magnets | C21: C2620/80 | C2711/90 | E21: 0.05 | G21: 10 | H21: [18] | I21: =I$16 -> 0.68 | J21: 0 | K21: 0.68 | L21: 0.8
B22: Tyre adhesives and paint dryers | C22: C2030/52 | D22: C20X - Manufacture of chemicals and chemical products | E22: 0.04 | G22: 1 | H22: [15] | I22: =I$16 -> 0.68 | J22: 0 | K22: 0.68 | L22: 0.8
B23: others | E23: 0.04 | G23: 1 | H23: [15] | I23: =I$16 -> 0.68 | J23: 0 | K23: 0.68 | L23: 0.8
A24: Dysprosium | B24: Air Conditioners | E24: 0.05 | F24: [10] | G24: 12 | H24: [10] | I24: 0.01 | J24: 0 | K24: 0.01 | L24: 0.8 | M24: [8]
B25: MRI Scanners | E25: 0.0167 | G25: 12 | H25: [10] | I25: =I$24 -> 0.01 | J25: 0 | K25: 0.01 | L25: 0.8
B26: Magnetic Separators | E26: 0.05 | G26: 20 | H26: [10] | I26: 0.01 | J26: 0 | K26: 0.01 | L26: 0.8
B27: Other Generators | E27: 0.0833 | G27: 20 | H27: [10] | I27: 0.01 | J27: 0 | K27: 0.01 | L27: 0.8
B28: Other Motors | E28: 0.5833 | G28: 13 | H28: [10] | I28: 0.01 | J28: 0 | K28: 0.01 | L28: 0.8
B29: Other NdFeB applications | E29: 0.2167 | G29: 10 | H29: [10] | I29: 0.01 | J29: 0 | K29: 0.01 | L29: 0.8
A30: Gadolinium | B30: Magnets | C30: C2599 | D30: C259 - Manufacture of other fabricated metal products | E30: 0.97 | F30: [13] | G30: 15 | H30: [16] | I30: 0.01 | J30: 0 | K30: 0.01 | L30: 0.8 | M30: [8]
B31: Medical and optical applications | C31: C2120 | D31: C212 - Manufacture of pharmaceutical preparations | E31: 0.03 | G31: 3 | H31: own assumption | I31: =I30 -> 0.01 | J31: 0 | K31: 0.01 | L31: 0.8
A32: Gallium | B32: Integrated Circuits | C32: C2610 | D32: C261 - Manufacture of electronic components and boards | E32: 0.74 | F32: [9] | G32: =G86 -> 7 | H32: own assumption based on 'Platinum - Electrical' | I32: 0.01 | J32: 0 | K32: 0.01 | L32: 0.8 | M32: [8]
B33: Lighting | C33: C2740 | D33: C274 - Manufacture of electric lighting equipment | E33: 0.26 | G33: =G45 -> 13 | H33: own assumption based on 'Indium - Semiconductors & LED' | I33: =I$32 -> 0.01 | J33: 0 | K33: 0.01 | L33: 0.8
B34: Magnets | E34: 0.03 | G34: =G30 -> 15 | H34: own assumption based on 'Gadolinium - Magnets' | I34: =I$32 -> 0.01 | J34: 0 | K34: 0.01 | L34: 0.8
B35: others | E35: 0.05 | G35: =G39 -> 5 | H35: own assumption based on 'Germanium - others' | I35: =I$32 -> 0.01 | J35: 0 | K35: 0.01 | L35: 0.8
A36: Germanium | B36: Polymer Catalyst | E36: 0.36 | F36: [9] | G36: =G60 -> 5 | H36: own assumption based on 'Lithium - Polymer Production' | I36: 0.01 | J36: 0 | K36: 0.01 | L36: 0.8 | M36: [8]
B37: Fibre Optics | C37: C2731 | D37: C273 - Manufacture of wiring and wiring devices | E37: 0.27 | G37: 14 | H37: [19] | I37: 0.01 | J37: 0 | K37: 0.01 | L37: 0.8
B38: Infrared Optics | C38: C2670 | D38: C267 - Manufacture of optical instruments and photographic equipment | E38: 0.26 | G38: 13 | H38: [19] | I38: 0.01 | J38: 0 | K38: 0.01 | L38: 0.8
B39: others | E39: 0.11 | G39: 5 | H39: [19] | I39: 0.01 | J39: 0 | K39: 0.01 | L39: 0.8
A40: Indium | B40: Flat Panel Display | C40: C2620 | D40: C262 - Manufacture of computers and peripheral equipment | E40: 0.61 | F40: [13] | G40: 7 | H40: [20] | I40: 0.01 | J40: 0 | K40: 0.01 | L40: 0.8 | M40: [8]
B41: Solders | C41: C2611 | D41: C261 - Manufacture of electronic components and boards | E41: 0.11 | G41: 13 | H41: [19] | I41: =I$40 -> 0.01 | J41: 0 | K41: 0.01 | L41: 0.8
...

Sheet Data_Junne
A1: Production
B3: Reference | C3: 1994 | D3: 1995 | E3: 1996 | F3: 1997 | G3: 1998 | H3: 1999 | I3: 2000 | J3: 2001 | K3: 2002 | L3: 2003 | M3: 2004 | N3: 2005 | O3: 2006 | P3: 2007 | Q3: 2008 | R3: 2009 | S3: 2010 | T3: 2011 | U3: 2012 | V3: 2013 | W3: 2014 | X3: 2015 | Y3: 2016 | Z3: 2017 | AA3: 2018
A4: Cobalt_Junne | B4: [1] | C4: 18500 | D4: 22100 | E4: 27000 | F4: 27000 | G4: 26300 | H4: 29900 | I4: 33300 | J4: 36700 | K4: 47600 | L4: 48400 | M4: 52400 | N4: 57900 | O4: 67500 | P4: 65500 | Q4: 75900 | R4: 72300 | S4: 89500 | T4: 109000 | U4: 103000 | V4: 110000 | W4: 123000 | X4: 126000 | Y4: 111000 | Z4: 120000 | AA4: 148000
A5: Lithium_Junne | B5: [1] | C5: 6100 | D5: 6300 | E5: 11000 | F5: 14000 | G5: 15000 | H5: 14000 | I5: 14000 | J5: 15100 | K5: 14200 | L5: 15100 | M5: 20200 | N5: 20600 | O5: 23500 | P5: 25800 | Q5: 25400 | R5: 18800 | S5: 28100 | T5: 34100 | U5: 35000 | V5: 34000 | W5: 31700 | X5: 31500 | Y5: 38000 | Z5: 69000 | AA5: 95000
A6: REE | B6: [1] | C6: 64500 | D6: 79900 | E6: 84800 | F6: 79700 | G6: 76600 | H6: 82000 | I6: 83500 | J6: 83500 | K6: 98300 | L6: 99100 | M6: 102000 | N6: 123000 | O6: 123000 | P6: 124000 | Q6: 124000 | R6: 133000 | S6: 133000 | T6: 111000 | U6: 110000 | V6: 110000 | W6: 123000 | X6: 130000 | Y6: 129000 | Z6: 132000 | AA6: 190000
A9: Economic Values
B11: Reference | C11: Unit | D11: 1990 | E11: 1991 | F11: 1992 | G11: 1993 | H11: 1994 | I11: 1995 | J11: 1996 | K11: 1997 | L11: 1998 | M11: 1999 | N11: 2000 | O11: 2001 | P11: 2002 | Q11: 2003 | R11: 2004 | S11: 2005 | T11: 2006 | U11: 2007 | V11: 2008 | W11: 2009 | X11: 2010 | Y11: 2011 | Z11: 2012 | AA11: 2013 | AB11: 2014 | AC11: 2015 | AD11: 2016 | AE11: 2017 | AF11: 2018 | AG11: 2019 | AH11: 2020 | AI11: 2021 | AJ11: 2022 | AK11: 2023 | AL11: 2024 | AM11: 2025 | AN11: 2026 | AO11: 2027 | AP11: 2028 | AQ11: 2029 | AR11: 2030 | AS11: 2031 | AT11: 2032 | AU11: 2033 | AV11: 2034 | AW11: 2035 | AX11: 2036 | AY11: 2037 | AZ11: 2038 | BA11: 2039 | BB11: 2040 | BC11: 2041 | BD11: 2042 | BE11: 2043 | BF11: 2044 | BG11: 2045 | BH11: 2046 | BI11: 2047 | BJ11: 2048 | BK11: 2049 | BL11: 2050
A12: GDP | B12: [15] | C12: $2018 | H12: 2.7775144e+13 | I12: 3.0871299e+13 | J12: 3.1554612e+13 | K12: 3.1439654e+13 | L12: 3.1378238e+13 | M12: 3.254267e+13 | N12: 3.3587694e+13 | O12: 3.3395802e+13 | P12: 3.4673852e+13 | Q12: 3.8902298e+13 | R12: 4.3816539e+13 | S12: 4.7457385e+13 | T12: 5.1448273e+13 | U12: 5.7968336e+13 | V12: 6.3611588e+13 | W12: 6.0334107e+13 | X12: 6.6051181e+13 | Y12: 7.3393152e+13 | Z12: 7.5085088e+13 | AA12: 7.7236276e+13 | AB12: 7.9332625e+13 | AC12: 75049412247228 | AD12: 7.6163841e+13 | AE12: 8.0950588e+13 | AF12: 8.5909727e+13
A13: GDP Growth | B13: [15] | C13: % | D13: 0.029031087 | E13: 0.014189821 | F13: 0.01767917 | G13: 0.019197217 | H13: 0.030093413 | I13: 0.030198107 | J13: 0.033850488 | K13: 0.037021175 | L13: 0.02531203 | M13: 0.032543355 | N13: 0.043891329 | O13: 0.01914173 | P13: 0.021574361 | Q13: 0.029053348 | R13: 0.044482888 | S13: 0.038298695 | T13: 0.043059442 | U13: 0.042291088 | V13: 0.018201778 | W13: -0.017351832 | X13: 0.043121769 | Y13: 0.031815369 | Z13: 0.025069382 | AA13: 0.026158898 | AB13: 0.028558724 | AC13: 0.028556781 | AD13: 0.025059089 | AE13: 0.031525283 | AF13: 0.031964547 | AG13: 0.031964547 | AH13: 0.031964547 | AI13: 0.031964547 | AJ13: 0.031964547 | AK13: 0.031964547 | AL13: 0.031964547 | AM13: 0.031964547 | AN13: 0.031964547 | AO13: 0.031964547 | AP13: 0.031964547 | AQ13: 0.031964547 | AR13: 0.031964547 | AS13: 0.031964547 | AT13: 0.031964547 | AU13: 0.031964547 | AV13: 0.031964547 | AW13: 0.031964547 | AX13: 0.031964547 | AY13: 0.031964547 | AZ13: 0.031964547 | BA13: 0.031964547 | BB13: 0.031964547 | BC13: 0.031964547 | BD13: 0.031964547 | BE13: 0.031964547 | BF13: 0.031964547 | BG13: 0.031964547 | BH13: 0.031964547 | BI13: 0.031964547 | BJ13: 0.031964547 | BK13: 0.031964547 | BL13: 0.031964547
A16: Recycled Content
B18: in % | C18: Reference | D18: 1994 | E18: 2011 | F18: 2015
A19: Cobalt_Junne | C19: [15] | D19: 0 | E19: 0.32 | F19: 0.4
A20: Dysprosium_Junne | C20: [15] | D20: 0 | E20: 0.05 | F20: 0.15
A21: Lithium_Junne | C21: [15] | D21: 0 | E21: 0.01 | F21: 0.1
A22: Neodym_Junne | C22: [15] | D22: 0 | E22: 0.05 | F22: 0.15
A25: Recycling
B27: in % | C27: Reference | D27: 1990 | E27: 2020 | F27: mod. 2050 | G27: amb. 2050
A28: Cobalt_Junne | B28: Batteries and Alloys | C28: [15] | D28: 0 | E28: 0.4 | F28: 0.4 | G28: 0.95
B29: Rest of Sub-Sectors | C29: [15] | D29: 0 | E29: 0.25 | F29: 0.25 | G29: 0.9
A30: Dysprosium_Junne | C30: [15] | D30: 0 | E30: 0 | F30: 0 | G30: 0
A31: Lithium_Junne | C31: [15] | D31: 0 | E31: 0 | F31: 0 | G31: 0
A32: Neodym_Junne | C32: [15] | D32: 0 | E32: 0 | F32: 0 | G32: 0
A35: REE-Factors
B37: in % | C37: Reference
A38: Dysprosium_Junne | B38: Share in REE Production | C38: [15] | D38: 0.009
B39: Conversion Factor Oxide to Element | C39: [15] | D39: 0.8713
A40: Neodym_Junne | B40: Share in REE Production | C40: [15] | D40: 0.162
B41: Conversion Factor Oxide to Element | C41: [15] | D41: 0.9334
A44: Non-Energy-Sector
B46: Subsectors | C46: Share in % | D46: Lifetime | E46: Growth Rates % | F46: Reference
A47: Cobalt_Junne | B47: Batteries | C47: 0.42 | D47: 5 | E47: 0.05 | F47: [15]
B48: Superalloys, hardfacing/HSS and other alloy | C48: 0.23 | D48: 1 | E48: 0.034
B49: Hard materials (carbides and diamond tools) | C49: 0.1 | D49: 1 | E49: 0.0264
B50: Catalysts | C50: 0.07 | D50: 1 | E50: -0.002
B51: Ceramics and Pigments | C51: 0.05 | D51: 1 | E51: -0.0079
B52: Magnets | C52: 0.05 | D52: 10 | E52: -0.0227
B53: Tyre adhesives and paint dryers | C53: 0.04 | D53: 1 | E53: -0.0144
B54: Others | C54: 0.04 | D54: 6 | E54: -0.0144
A55: Dysprosium_Junne | B55: Air conditioners | C55: 0.049997667 | D55: 12 | E55: 0.09 | F55: [15]
B56: MRI scanners | C56: 0.016665889 | D56: 12 | E56: -0.08
...

Sheet Cadmium
A1: TYPE
A2: HI | B2: =MID(CELL("Dateiname",$B$2),FIND("]", CELL("Dateiname",$B$2))+1,31)&" HI" -> #VALUE! | C2: unit | D2: 1990 | E2: =D2+1 -> 1991 | F2: =E2+1 -> 1992 | G2: =F2+1 -> 1993 | H2: =G2+1 -> 1994 | I2: =H2+1 -> 1995 | J2: =I2+1 -> 1996 | K2: =J2+1 -> 1997 | L2: =K2+1 -> 1998 | ... DJ2: =DI2+1 -> 2100 | DK2: Python does not read anything right of this line!
A3: HI | B3: ='Data Non-Energy-Sector'!B5 -> Batteries | C3: t/a | D3: =D95 -> 13410.277 | E3: =E95 -> 13794.086 | F3: =F95 -> 14002.4 | G3: =G95 -> 14251.491 | H3: =H95 -> 14464.407 | I3: =I95 -> 15186.824 | J3: =J95 -> 15949.625 | K3: =K95 -> 17364.599 | ... DJ3: =DJ95 -> 465057.02
A4: HI | B4: ='Data Non-Energy-Sector'!B6 -> Pigments | C4: t/a | D4: =D96 -> 1843.9131 | E4: =E96 -> 1896.6868 | F4: =F96 -> 1925.33 | G4: =G96 -> 1959.58 | H4: =H96 -> 1988.856 | I4: =I96 -> 2088.1884 | J4: =J96 -> 2193.0734 | K4: =K96 -> 2387.6324 | ... DJ4: =DJ96 -> 63945.34
A5: HI | B5: ='Data Non-Energy-Sector'!B7 -> Coatings | C5: t/a | D5: =D97 -> 1173.3993 | E5: =E97 -> 1206.9825 | F5: =F97 -> 1225.21 | G5: =G97 -> 1247.0055 | H5: =H97 -> 1265.6357 | I5: =I97 -> 1328.8471 | J5: =J97 -> 1395.5922 | K5: =K97 -> 1519.4024 | ... DJ5: =DJ97 -> 40692.489
A6: HI | B6: ='Data Non-Energy-Sector'!B8 -> Stabilisers | C6: t/a | D6: =D98 -> 335.25693 | E6: =E98 -> 344.85215 | F6: =F98 -> 350.05999 | G6: =G98 -> 356.28727 | H6: =H98 -> 361.61019 | I6: =I98 -> 379.67061 | J6: =J98 -> 398.74062 | K6: =K98 -> 434.11498 | ... DJ6: =DJ98 -> 11626.425
A7: HI | B7: - | C7: t/a
A8: HI | B8: - | C8: t/a
A9: HI | B9: - | C9: t/a
A10: HI | B10: - | C10: t/a
A11: HI | B11: - | C11: t/a
A12: HI | B12: - | C12: t/a
A13: HI | B13: - | C13: t/a
A14: HI | B14: - | C14: t/a
A15: HI | B15: - | C15: t/a
A16: HI | B16: - | C16: t/a
A17: HI | B17: - | C17: t/a
A18: HI | B18: - | C18: t/a
... A22: HI | B22: - | C22: t/a
B23: Total | C23: t/a | D23: =SUM(D3:D22) -> 16762.847 | E23: =SUM(E3:E22) -> 17242.608 | F23: =SUM(F3:F22) -> 17503 | G23: =SUM(G3:G22) -> 17814.364 | H23: =SUM(H3:H22) -> 18080.509 | I23: =SUM(I3:I22) -> 18983.53 | J23: =SUM(J3:J22) -> 19937.031 | K23: =SUM(K3:K22) -> 21705.749 | ... DJ23: =SUM(DJ3:DJ22) -> 581321.27
A25: LO | B25: =MID(CELL("Dateiname",$B$2),FIND("]", CELL("Dateiname",$B$2))+1,31)&" LO" -> #VALUE! | C25: =C2 -> unit | D25: =D2 -> 1990 | E25: =E2 -> 1991 | F25: =F2 -> 1992 | G25: =G2 -> 1993 | H25: =H2 -> 1994 | I25: =I2 -> 1995 | J25: =J2 -> 1996 | ... DJ25: =DJ2 -> 2100
A26: LO | B26: =B3 -> Batteries | C26: =C3 -> t/a | D26: =D3 -> 13410.277 | E26: =E3 -> 13794.086 | F26: =F3 -> 14002.4 | G26: =G3 -> 14251.491 | H26: =H3 -> 14464.407 | I26: =I3 -> 15186.824 | ... AF26: =AF3 -> 36398.255 | AG26: =AG100 -> 36261.914 | AH26: =AH100 -> 37422.295 | AI26: =AI100 -> 38619.809 | AJ26: =AJ100 -> 39855.642 | AK26: =AK100 -> 41131.023 | AL26: =AL100 -> 42447.216 | AM26: =AM100 -> 43805.527 | AN26: =AN100 -> 45207.303 | ... DJ26: =DJ100 -> 465057.02
A27: LO | B27: =B4 -> Pigments | C27: =C4 -> t/a | D27: =D4 -> 1843.9131 | E27: =E4 -> 1896.6868 | F27: =F4 -> 1925.33 | G27: =G4 -> 1959.58 | H27: =H4 -> 1988.856 | I27: =I4 -> 2088.1884 | ... AF27: =AF4 -> 5004.7601 | AG27: =AG101 -> 4986.0132 | AH27: =AH101 -> 5145.5656 | AI27: =AI101 -> 5310.2237 | AJ27: =AJ101 -> 5480.1508 | AK27: =AK101 -> 5655.5157 | AL27: =AL101 -> 5836.4922 | AM27: =AM101 -> 6023.2599 | AN27: =AN101 -> 6216.0042 | ... DJ27: =DJ101 -> 63945.34
A28: LO | B28: =B5 -> Coatings | C28: =C5 -> t/a | D28: =D5 -> 1173.3993 | E28: =E5 -> 1206.9825 | F28: =F5 -> 1225.21 | G28: =G5 -> 1247.0055 | H28: =H5 -> 1265.6357 | I28: =I5 -> 1328.8471 | ... AF28: =AF5 -> 3184.8473 | AG28: =AG102 -> 3172.9175 | AH28: =AH102 -> 3274.4508 | AI28: =AI102 -> 3379.2332 | AJ28: =AJ102 -> 3487.3687 | AK28: =AK102 -> 3598.9645 | AL28: =AL102 -> 3714.1314 | AM28: =AM102 -> 3832.9836 | AN28: =AN102 -> 3955.6391 | ... DJ28: =DJ102 -> 40692.489
A29: LO | B29: =B6 -> Stabilisers | C29: =C6 -> t/a | D29: =D6 -> 335.25693 | E29: =E6 -> 344.85215 | F29: =F6 -> 350.05999 | G29: =G6 -> 356.28727 | H29: =H6 -> 361.61019 | I29: =I6 -> 379.67061 | ... AF29: =AF6 -> 909.95638 | AG29: =AG103 -> 906.54785 | AH29: =AH103 -> 935.55738 | AI29: =AI103 -> 965.49521 | AJ29: =AJ103 -> 996.39106 | AK29: =AK103 -> 1028.2756 | AL29: =AL103 -> 1061.1804 | AM29: =AM103 -> 1095.1382 | AN29: =AN103 -> 1130.1826 | ... DJ29: =DJ103 -> 11626.425
A30: LO | B30: =B7 -> - | C30: =C7 -> t/a
A31: LO | B31: =B8 -> - | C31: =C8 -> t/a
A32: LO | B32: =B9 -> - | C32: =C9 -> t/a
A33: LO | B33: =B10 -> - | C33: =C10 -> t/a
A34: LO | B34: =B11 -> - | C34: =C11 -> t/a
A35: LO | B35: =B12 -> - | C35: =C12 -> t/a
A36: LO | B36: =B13 -> - | C36: =C13 -> t/a
A37: LO | B37: =B14 -> - | C37: =C14 -> t/a
A38: LO | B38: =B15 -> - | C38: =C15 -> t/a
A39: LO | B39: =B16 -> - | C39: =C16 -> t/a
A40: LO | B40: =B17 -> - | C40: =C17 -> t/a
A41: LO | B41: =B18 -> - | C41: =C18 -> t/a
... A45: LO | B45: =B22 -> - | C45: =C22 -> t/a
B46: Total | C46: t/a | D46: =SUM(D26:D45) -> 16762.847 | E46: =SUM(E26:E45) -> 17242.608 | F46: =SUM(F26:F45) -> 17503 | G46: =SUM(G26:G45) -> 17814.364 | H46: =SUM(H26:H45) -> 18080.509 | I46: =SUM(I26:I45) -> 18983.53 | J46: =SUM(J26:J45) -> 19937.031 | K46: =SUM(K26:K45) -> 21705.749 | ... DJ46: =SUM(DJ26:DJ45) -> 581321.27
A48: RECY | B48: =MID(CELL("Dateiname",$B$2),FIND("]", CELL("Dateiname",$B$2))+1,31) -> #VALUE! | C48: temp | D48: recyMod1 | E48: recyMod2 | F48: recyMod3 | G48: recyMod4 | H48: recyMod5 | I48: recyMod6 | J48: recyMod7 | K48: recyAmb1 | L48: recyAmb2 | M48: recyAmb3 | N48: recyAmb4 | O48: recyAmb5 | P48: recyAmb6 | Q48: recyAmb7 | R48: tau | S48: growthrate
...

Sheet Cerium
A1: TYPE
A2: HI | B2: =MID(CELL("Dateiname",$B$2),FIND("]", CELL("Dateiname",$B$2))+1,31)&" HI" -> #VALUE! | C2: unit | D2: 1990 | E2: =D2+1 -> 1991 | F2: =E2+1 -> 1992 | G2: =F2+1 -> 1993 | H2: =G2+1 -> 1994 | I2: =H2+1 -> 1995 | J2: =I2+1 -> 1996 | K2: =J2+1 -> 1997 | L2: =K2+1 -> 1998 | ... DJ2: =DI2+1 -> 2100 | DK2: Python does not read anything right of this line!
A3: HI | B3: ='Data Non-Energy-Sector'!B9 -> Autocatalyst | C3: t/a | D3: =D102 -> 8054.1451 | E3: =E102 -> 8294.0235 | F3: =F102 -> 8419.1356 | G3: =G102 -> 8568.7385 | H3: =H102 -> 8696.6151 | I3: =I102 -> 10773.016 | J3: =J102 -> 11433.689 | K3: =K102 -> 10746.05 | ... DJ3: =DJ102 -> 363132.66
A4: HI | B4: ='Data Non-Energy-Sector'!B10 -> Glass & Ceramics | C4: t/a | D4: =D103 -> 7593.9082 | E4: =E103 -> 7820.0793 | F4: =F103 -> 7938.0421 | G4: =G103 -> 8079.0963 | H4: =H103 -> 8199.6657 | I4: =I103 -> 10157.415 | J4: =J103 -> 10780.336 | K4: =K103 -> 10131.99 | ... DJ4: =DJ103 -> 342382.22
A5: HI | B5: ='Data Non-Energy-Sector'!B11 -> Polishing Powders | C5: t/a | D5: =D104 -> 2531.3027 | E5: =E104 -> 2606.6931 | F5: =F104 -> 2646.014 | G5: =G104 -> 2693.0321 | H5: =H104 -> 2733.2219 | I5: =I104 -> 3385.8051 | J5: =J104 -> 3593.4452 | K5: =K104 -> 3377.33 | ... DJ5: =DJ104 -> 114127.41
A6: HI | B6: ='Data Non-Energy-Sector'!B12 -> Fluid Cracking Catalysts | C6: t/a | D6: =D105 -> 1840.9474 | E6: =E105 -> 1895.7768 | F6: =F105 -> 1924.3739 | G6: =G105 -> 1958.5688 | H6: =H105 -> 1987.7977 | I6: =I105 -> 2462.4037 | J6: =J105 -> 2613.4147 | K6: =K105 -> 2456.24 | ... DJ6: =DJ105 -> 83001.751
A7: HI | B7: ='Data Non-Energy-Sector'!B13 -> Metal | C7: t/a | D7: =D106 -> 1380.7106 | E7: =E106 -> 1421.8326 | F7: =F106 -> 1443.2804 | G7: =G106 -> 1468.9266 | H7: =H106 -> 1490.8483 | I7: =I106 -> 1846.8028 | J7: =J106 -> 1960.061 | K7: =K106 -> 1842.18 | ... DJ7: =DJ106 -> 62251.313
A8: HI | B8: ='Data Non-Energy-Sector'!B14 -> Batteries | C8: t/a | D8: =D107 -> 1380.7106 | E8: =E107 -> 1421.8326 | F8: =F107 -> 1443.2804 | G8: =G107 -> 1468.9266 | H8: =H107 -> 1490.8483 | I8: =I107 -> 1846.8028 | J8: =J107 -> 1960.061 | K8: =K107 -> 1842.18 | ... DJ8: =DJ107 -> 62251.313
A9: HI | B9: ='Data Non-Energy-Sector'!B15 -> Lighting | C9: t/a | D9: =D108 -> 230.11843 | E9: =E108 -> 236.9721 | F9: =F108 -> 240.54673 | G9: =G108 -> 244.8211 | H9: =H108 -> 248.47472 | I9: =I108 -> 307.80046 | J9: =J108 -> 326.67684 | K9: =K108 -> 307.03 | ... DJ9: =DJ108 -> 10375.219
A10: HI | B10: - | C10: t/a
A11: HI | B11: - | C11: t/a
A12: HI | B12: - | C12: t/a
A13: HI | B13: - | C13: t/a
A14: HI | B14: - | C14: t/a
A15: HI | B15: - | C15: t/a
A16: HI | B16: - | C16: t/a
A17: HI | B17: - | C17: t/a
A18: HI | B18: - | C18: t/a
A19: HI | B19: - | C19: t/a
A20: HI | B20: - | C20: t/a
A21: HI | B21: - | C21: t/a
A22: HI | B22: - | C22: t/a
B23: Total | C23: t/a | D23: =SUM(D3:D22) -> 23011.843 | E23: =SUM(E3:E22) -> 23697.21 | F23: =SUM(F3:F22) -> 24054.673 | G23: =SUM(G3:G22) -> 24482.11 | H23: =SUM(H3:H22) -> 24847.472 | I23: =SUM(I3:I22) -> 30780.046 | J23: =SUM(J3:J22) -> 32667.684 | K23: =SUM(K3:K22) -> 30703 | ... DJ23: =SUM(DJ3:DJ22) -> 1037521.9
A25: LO | B25: =MID(CELL("Dateiname",$B$2),FIND("]", CELL("Dateiname",$B$2))+1,31)&" LO" -> #VALUE! | C25: =C2 -> unit | D25: =D2 -> 1990 | E25: =E2 -> 1991 | F25: =F2 -> 1992 | G25: =G2 -> 1993 | H25: =H2 -> 1994 | I25: =I2 -> 1995 | J25: =J2 -> 1996 | ... DJ25: =DJ2 -> 2100
A26: LO | B26: =B3 -> Autocatalyst | C26: =C3 -> t/a | D26: =D3 -> 8054.1451 | E26: =E3 -> 8294.0235 | F26: =F3 -> 8419.1356 | G26: =G3 -> 8568.7385 | H26: =H3 -> 8696.6151 | I26: =I3 -> 10773.016 | ... AF26: =AF3 -> 25617.936 | AG26: =AG110 -> 28314.561 | AH26: =AH110 -> 29220.627 | AI26: =AI110 -> 30155.687 | AJ26: =AJ110 -> 31120.669 | AK26: =AK110 -> 32116.53 | AL26: =AL110 -> 33144.259 | AM26: =AM110 -> 34204.875 | AN26: =AN110 -> 35299.431 | ... DJ26: =DJ110 -> 363132.66
A27: LO | B27: =B4 -> Glass & Ceramics | C27: =C4 -> t/a | D27: =D4 -> 7593.9082 | E27: =E4 -> 7820.0793 | F27: =F4 -> 7938.0421 | G27: =G4 -> 8079.0963 | H27: =H4 -> 8199.6657 | I27: =I4 -> 10157.415 | ... AF27: =AF4 -> 24154.054 | AG27: =AG111 -> 26696.586 | AH27: =AH111 -> 27550.877 | AI27: =AI111 -> 28432.505 | AJ27: =AJ111 -> 29342.345 | AK27: =AK111 -> 30281.3 | AL27: =AL111 -> 31250.302 | AM27: =AM111 -> 32250.311 | AN27: =AN111 -> 33282.321 | ... DJ27: =DJ111 -> 342382.22
A28: LO | B28: =B5 -> Polishing Powders | C28: =C5 -> t/a | D28: =D5 -> 2531.3027 | E28: =E5 -> 2606.6931 | F28: =F5 -> 2646.014 | G28: =G5 -> 2693.0321 | H28: =H5 -> 2733.2219 | I28: =I5 -> 3385.8051 | ... AF28: =AF5 -> 8051.3513 | AG28: =AG112 -> 8898.862 | AH28: =AH112 -> 9183.6256 | AI28: =AI112 -> 9477.5016 | AJ28: =AJ112 -> 9780.7816 | AK28: =AK112 -> 10093.767 | AL28: =AL112 -> 10416.767 | AM28: =AM112 -> 10750.104 | AN28: =AN112 -> 11094.107 | ... DJ28: =DJ112 -> 114127.41
A29: LO | B29: =B6 -> Fluid Cracking Catalysts | C29: =C6 -> t/a | D29: =D6 -> 1840.9474 | E29: =E6 -> 1895.7768 | F29: =F6 -> 1924.3739 | G29: =G6 -> 1958.5688 | H29: =H6 -> 1987.7977 | I29: =I6 -> 2462.4037 | ... AF29: =AF6 -> 5855.5282 | AG29: =AG113 -> 6471.8996 | AH29: =AH113 -> 6679.0004 | AI29: =AI113 -> 6892.7284 | AJ29: =AJ113 -> 7113.2957 | AK29: =AK113 -> 7340.9212 | AL29: =AL113 -> 7575.8307 | AM29: =AM113 -> 7818.2572 | AN29: =AN113 -> 8068.4415 | ... DJ29: =DJ113 -> 83001.751
A30: LO | B30: =B7 -> Metal | C30: =C7 -> t/a | D30: =D7 -> 1380.7106 | E30: =E7 -> 1421.8326 | F30: =F7 -> 1443.2804 | G30: =G7 -> 1468.9266 | H30: =H7 -> 1490.8483 | I30: =I7 -> 1846.8028 | ... AF30: =AF7 -> 4391.6462 | AG30: =AG114 -> 4853.9247 | AH30: =AH114 -> 5009.2503 | AI30: =AI114 -> 5169.5463 | AJ30: =AJ114 -> 5334.9718 | AK30: =AK114 -> 5505.6909 | AL30: =AL114 -> 5681.873 | AM30: =AM114 -> 5863.6929 | AN30: =AN114 -> 6051.3311 | ... DJ30: =DJ114 -> 62251.313
A31: LO | B31: =B8 -> Batteries | C31: =C8 -> t/a | D31: =D8 -> 1380.7106 | E31: =E8 -> 1421.8326 | F31: =F8 -> 1443.2804 | G31: =G8 -> 1468.9266 | H31: =H8 -> 1490.8483 | I31: =I8 -> 1846.8028 | ... AF31: =AF8 -> 4391.6462 | AG31: =AG115 -> 4853.9247 | AH31: =AH115 -> 5009.2503 | AI31: =AI115 -> 5169.5463 | AJ31: =AJ115 -> 5334.9718 | AK31: =AK115 -> 5505.6909 | AL31: =AL115 -> 5681.873 | AM31: =AM115 -> 5863.6929 | AN31: =AN115 -> 6051.3311 | ... DJ31: =DJ115 -> 62251.313
A32: LO | B32: =B9 -> Lighting | C32: =C9 -> t/a | D32: =D9 -> 230.11843 | E32: =E9 -> 236.9721 | F32: =F9 -> 240.54673 | G32: =G9 -> 244.8211 | H32: =H9 -> 248.47472 | I32: =I9 -> 307.80046 | ... AF32: =AF9 -> 731.94103 | AG32: =AG116 -> 808.98745 | AH32: =AH116 -> 834.87505 | AI32: =AI116 -> 861.59105 | AJ32: =AJ116 -> 889.16197 | AK32: =AK116 -> 917.61515 | AL32: =AL116 -> 946.97883 | AM32: =AM116 -> 977.28216 | AN32: =AN116 -> 1008.5552 | ... DJ32: =DJ116 -> 10375.219
A33: LO | B33: =B10 -> - | C33: =C10 -> t/a
A34: LO | B34: =B11 -> - | C34: =C11 -> t/a
A35: LO | B35: =B12 -> - | C35: =C12 -> t/a
A36: LO | B36: =B13 -> - | C36: =C13 -> t/a
A37: LO | B37: =B14 -> - | C37: =C14 -> t/a
A38: LO | B38: =B15 -> - | C38: =C15 -> t/a
A39: LO | B39: =B16 -> - | C39: =C16 -> t/a
A40: LO | B40: =B17 -> - | C40: =C17 -> t/a
A41: LO | B41: =B18 -> - | C41: =C18 -> t/a
...

Sheet Cobalt
A1: TYPE
A2: HI | B2: =MID(CELL("Dateiname",$B$2),FIND("]", CELL("Dateiname",$B$2))+1,31)&" HI" -> #VALUE! | C2: unit | D2: 1990 | E2: =D2+1 -> 1991 | F2: =E2+1 -> 1992 | G2: =F2+1 -> 1993 | H2: =G2+1 -> 1994 | I2: =H2+1 -> 1995 | J2: =I2+1 -> 1996 | K2: =J2+1 -> 1997 | L2: =K2+1 -> 1998 | ... DJ2: =DI2+1 -> 2100 | DK2: Python does not read anything right of this line!
A3: HI | B3: ='Data Non-Energy-Sector'!B16 -> Batteries | C3: t/a | D3: =D99 -> 7195.9845 | E3: =E99 -> 7190.4357 | F3: =F99 -> 7302.2173 | G3: =G99 -> 7435.8801 | H3: =H99 -> 7550.1316 | I3: =I99 -> 9240.2036 | J3: =J99 -> 11563.75 | K3: =K99 -> 11798.835 | ... DJ3: =DJ99 -> 974944.25
A4: HI | B4: ='Data Non-Energy-Sector'!B17 -> Superlloys, hardfacing/HSS and other alloy | C4: t/a | D4: =D100 -> 3940.6582 | E4: =E100 -> 3937.6196 | F4: =F100 -> 3998.8333 | G4: =G100 -> 4072.0296 | H4: =H100 -> 4134.5959 | I4: =I100 -> 5060.1115 | J4: =J100 -> 6332.5299 | K4: =K100 -> 6461.2667 | ... DJ4: =DJ100 -> 533898.04
A5: HI | B5: ='Data Non-Energy-Sector'!B18 -> Hard materials (carbides and diamond tools) | C5: t/a | D5: =D101 -> 1713.3296 | E5: =E101 -> 1712.0085 | F5: =F101 -> 1738.6232 | G5: =G101 -> 1770.4476 | H5: =H101 -> 1797.6504 | I5: =I101 -> 2200.0485 | J5: =J101 -> 2753.2739 | K5: =K101 -> 2809.2464 | ... DJ5: =DJ101 -> 232129.58
A6: HI | B6: ='Data Non-Energy-Sector'!B19 -> Catalysts | C6: t/a | D6: =D102 -> 1199.3307 | E6: =E102 -> 1198.406 | F6: =F102 -> 1217.0362 | G6: =G102 -> 1239.3134 | H6: =H102 -> 1258.3553 | I6: =I102 -> 1540.0339 | J6: =J102 -> 1927.2917 | K6: =K102 -> 1966.4725 | ... DJ6: =DJ102 -> 162490.71
A7: HI | B7: ='Data Non-Energy-Sector'!B20 -> Ceramic & Pigments | C7: t/a | D7: =D103 -> 856.66482 | E7: =E103 -> 856.00425 | F7: =F103 -> 869.31158 | G7: =G103 -> 885.22382 | H7: =H103 -> 898.8252 | I7: =I103 -> 1100.0242 | J7: =J103 -> 1376.6369 | K7: =K103 -> 1404.6232 | ... DJ7: =DJ103 -> 116064.79
A8: HI | B8: ='Data Non-Energy-Sector'!B21 -> Magnets | C8: t/a | D8: =D104 -> 856.66482 | E8: =E104 -> 856.00425 | F8: =F104 -> 869.31158 | G8: =G104 -> 885.22382 | H8: =H104 -> 898.8252 | I8: =I104 -> 1100.0242 | J8: =J104 -> 1376.6369 | K8: =K104 -> 1404.6232 | ... DJ8: =DJ104 -> 116064.79
A9: HI | B9: ='Data Non-Energy-Sector'!B22 -> Tyre adhesives and paint dryers | C9: t/a | D9: =D105 -> 685.33185 | E9: =E105 -> 684.8034 | F9: =F105 -> 695.44927 | G9: =G105 -> 708.17906 | H9: =H105 -> 719.06016 | I9: =I105 -> 880.01939 | J9: =J105 -> 1101.3095 | K9: =K105 -> 1123.6986 | ... DJ9: =DJ105 -> 92851.833
A10: HI | B10: ='Data Non-Energy-Sector'!B23 -> others | C10: t/a | D10: =D106 -> 685.33185 | E10: =E106 -> 684.8034 | F10: =F106 -> 695.44927 | G10: =G106 -> 708.17906 | H10: =H106 -> 719.06016 | I10: =I106 -> 880.01939 | J10: =J106 -> 1101.3095 | K10: =K106 -> 1123.6986 | ... DJ10: =DJ106 -> 92851.833
A11: HI | B11: - | C11: t/a
A12: HI | B12: - | C12: t/a
A13: HI | B13: - | C13: t/a
A14: HI | B14: - | C14: t/a
A15: HI | B15: - | C15: t/a
A16: HI | B16: - | C16: t/a
A17: HI | B17: - | C17: t/a
A18: HI | B18: - | C18: t/a
A19: HI | B19: - | C19: t/a
A20: HI | B20: - | C20: t/a
A21: HI | B21: - | C21: t/a
A22: HI | B22: - | C22: t/a
B23: Total | C23: t/a | D23: =SUM(D3:D22) -> 17133.296 | E23: =SUM(E3:E22) -> 17120.085 | F23: =SUM(F3:F22) -> 17386.232 | G23: =SUM(G3:G22) -> 17704.476 | H23: =SUM(H3:H22) -> 17976.504 | I23: =SUM(I3:I22) -> 22000.485 | J23: =SUM(J3:J22) -> 27532.739 | K23: =SUM(K3:K22) -> 28092.464 | ... DJ23: =SUM(DJ3:DJ22) -> 2321295.8
A25: LO | B25: =MID(CELL("Dateiname",$B$2),FIND("]", CELL("Dateiname",$B$2))+1,31)&" LO" -> #VALUE! | C25: =C2 -> unit | D25: =D2 -> 1990 | E25: =E2 -> 1991 | F25: =F2 -> 1992 | G25: =G2 -> 1993 | H25: =H2 -> 1994 | I25: =I2 -> 1995 | J25: =J2 -> 1996 | ... DJ25: =DJ2 -> 2100
A26: LO | B26: =B3 -> Batteries | C26: =C3 -> t/a | D26: =D3 -> 7195.9845 | E26: =E3 -> 7190.4357 | F26: =F3 -> 7302.2173 | G26: =G3 -> 7435.8801 | H26: =H3 -> 7550.1316 | I26: =I3 -> 9240.2036 | ... AF26: =AF3 -> 82136.26 | AG26: =AG108 -> 76019.376 | AH26: =AH108 -> 78451.996 | AI26: =AI108 -> 80962.46 | AJ26: =AJ108 -> 83553.258 | AK26: =AK108 -> 86226.963 | AL26: =AL108 -> 88986.226 | AM26: =AM108 -> 91833.785 | AN26: =AN108 -> 94772.466 | ... DJ26: =DJ108 -> 974944.25
A27: LO | B27: =B4 -> Superlloys, hardfacing/HSS and other alloy | C27: =C4 -> t/a | D27: =D4 -> 3940.6582 | E27: =E4 -> 3937.6196 | F27: =F4 -> 3998.8333 | G27: =G4 -> 4072.0296 | H27: =H4 -> 4134.5959 | I27: =I4 -> 5060.1115 | ... AF27: =AF4 -> 44979.381 | AG27: =AG109 -> 41629.658 | AH27: =AH109 -> 42961.807 | AI27: =AI109 -> 44336.585 | AJ27: =AJ109 -> 45755.356 | AK27: =AK109 -> 47219.527 | AL27: =AL109 -> 48730.552 | AM27: =AM109 -> 50289.93 | AN27: =AN109 -> 51899.207 | ... DJ27: =DJ109 -> 533898.04
A28: LO | B28: =B5 -> Hard materials (carbides and diamond tools) | C28: =C5 -> t/a | D28: =D5 -> 1713.3296 | E28: =E5 -> 1712.0085 | F28: =F5 -> 1738.6232 | G28: =G5 -> 1770.4476 | H28: =H5 -> 1797.6504 | I28: =I5 -> 2200.0485 | ... AF28: =AF5 -> 19556.252 | AG28: =AG110 -> 18099.851 | AH28: =AH110 -> 18679.047 | AI28: =AI110 -> 19276.776 | AJ28: =AJ110 -> 19893.633 | AK28: =AK110 -> 20530.229 | AL28: =AL110 -> 21187.197 | AM28: =AM110 -> 21865.187 | AN28: =AN110 -> 22564.873 | ... DJ28: =DJ110 -> 232129.58
